Workbook

Sheet assumptions
B1: base case | C1: social contagion high | D1: professionalization high | E1: both high | H1: Projects | R1: Ecs | AB1: Installed capacity | AL1: Members
A2: willing to initiate | B2: 0.71 | C2: 0.71 | H2: 1 | I2: 2 | J2: 3 | K2: 4 | L2: 5 | M2: 6 | N2: 7 | O2: 8 | P2: 9 | R2: 1 | S2: 2 | T2: 3 | U2: 4 | V2: 5 | W2: 6 | X2: 7 | Y2: 8 | Z2: 9 | AB2: 1 | AC2: 2 | AD2: 3 | AE2: 4 | AF2: 5 | AG2: 6 | AH2: 7 | AI2: 8 | AJ2: 9 | AL2: 1 | AM2: 2 | AN2: 3 | AO2: 4 | AP2: 5 | AQ2: 6 | AR2: 7 | AS2: 8 | AT2: 9
A3: willing to invest | B3: 0.66 | C3: 0.66 | G3: year | H3: base | I3: very high contagion | J3: very high ind lr and high col lr | K3: very high clr | L3: verhy high clr and high ilr | M3: very high both lrs | N3: verhy high lrs and high max projects | O3: verhy high lrs and high max projects and hybrid | P3: base_network update | R3: base | S3: very high contagion | T3: very high ind lr and high col lr | U3: very high clr | V3: verhy high clr and high ilr | W3: very high both lrs | X3: verhy high lrs and high max projects | Y3: verhy high lrs and high max projects and hybrid | Z3: base_network update | AB3: base | AC3: very high contagion | AD3: very high ind lr and high col lr | AE3: very high clr | AF3: verhy high clr and high ilr | AG3: very high both lrs | AH3: verhy high lrs and high max projects | AI3: verhy high lrs and high max projects and hybrid | AJ3: base_network update | AL3: base | AM3: very high contagion | AN3: very high ind lr and high col lr | AO3: very high clr | AP3: verhy high clr and high ilr | AQ3: very high both lrs | AR3: verhy high lrs and high max projects | AS3: verhy high lrs and high max projects and hybrid | AT3: base_network update
A4: professional capacity | B4: 0.7 | C4: 0.7 | G4: 2009 | H4: =AVERAGEIF(baseCase_projects!$B$63:$BC$63,assumptions!H$2,baseCase_projects!$B2:$BC2) -> 1 | I4: =AVERAGEIF(baseCase_projects!$B$63:$BC$63,assumptions!I$2,baseCase_projects!$B2:$BC2) -> 1 | J4: =AVERAGEIF(baseCase_projects!$B$63:$BC$63,assumptions!J$2,baseCase_projects!$B2:$BC2) -> 1 | K4: =AVERAGEIF(baseCase_projects!$B$63:$BC$63,assumptions!K$2,baseCase_projects!$B2:$BC2) -> 1 | L4: =AVERAGEIF(baseCase_projects!$B$63:$BC$63,assumptions!L$2,baseCase_projects!$B2:$BC2) -> 1 | M4: =AVERAGEIF(baseCase_projects!$B$63:$BC$63,assumptions!M$2,baseCase_projects!$B2:$BC2) -> 1 | N4: =AVERAGEIF(baseCase_projects!$B$63:$BC$63,assumptions!N$2,baseCase_projects!$B2:$BC2) -> 1 | O4: =AVERAGEIF(baseCase_projects!$B$63:$BC$63,assumptions!O$2,baseCase_projects!$B2:$BC2) -> 1 | P4: =AVERAGEIF(baseCase_projects!$B$63:$BC$63,assumptions!P$2,baseCase_projects!$B2:$BC2) -> 1 | R4: =AVERAGEIF(baseCase_ECs!$B$63:$BC$63,assumptions!R$2,baseCase_ECs!$B2:$BC2) -> 20 | S4: =AVERAGEIF(baseCase_ECs!$B$63:$BC$63,assumptions!S$2,baseCase_ECs!$B2:$BC2) -> 20 | T4: =AVERAGEIF(baseCase_ECs!$B$63:$BC$63,assumptions!T$2,baseCase_ECs!$B2:$BC2) -> 20 | U4: =AVERAGEIF(baseCase_ECs!$B$63:$BC$63,assumptions!U$2,baseCase_ECs!$B2:$BC2) -> 20 | V4: =AVERAGEIF(baseCase_ECs!$B$63:$BC$63,assumptions!V$2,baseCase_ECs!$B2:$BC2) -> 20 | W4: =AVERAGEIF(baseCase_ECs!$B$63:$BC$63,assumptions!W$2,baseCase_ECs!$B2:$BC2) -> 20 | X4: =AVERAGEIF(baseCase_ECs!$B$63:$BC$63,assumptions!X$2,baseCase_ECs!$B2:$BC2) -> 20 | Y4: =AVERAGEIF(baseCase_ECs!$B$63:$BC$63,assumptions!Y$2,baseCase_ECs!$B2:$BC2) -> 20 | Z4: =AVERAGEIF(baseCase_ECs!$B$63:$BC$63,assumptions!Z$2,baseCase_ECs!$B2:$BC2) -> 20 | AB4: =AVERAGEIF(baseCase_installedCap!$B$63:$BC$63,assumptions!AB$2,baseCase_installedCap!$B2:$BC2) -> 447 | AC4: =AVERAGEIF(baseCase_installedCap!$B$63:$BC$63,assumptions!AC$2,baseCase_installedCap!$B2:$BC2) -> 447 | AD4: =AVERAGEIF(baseCase_installedCap!$B$63:$BC$63,assumptions!AD$2,baseCase_installedCap!$B2:$BC2) -> 447 | AE4: =AVERAGEIF(baseCase_installedCap!$B$63:$BC$63,assumptions!AE$2,baseCase_installedCap!$B2:$BC2) -> 447 | AF4: =AVERAGEIF(baseCase_installedCap!$B$63:$BC$63,assumptions!AF$2,baseCase_installedCap!$B2:$BC2) -> 447 | AG4: =AVERAGEIF(baseCase_installedCap!$B$63:$BC$63,assumptions!AG$2,baseCase_installedCap!$B2:$BC2) -> 447 | AH4: =AVERAGEIF(baseCase_installedCap!$B$63:$BC$63,assumptions!AH$2,baseCase_installedCap!$B2:$BC2) -> 447 | AI4: =AVERAGEIF(baseCase_installedCap!$B$63:$BC$63,assumptions!AI$2,baseCase_installedCap!$B2:$BC2) -> 447 | AJ4: =AVERAGEIF(baseCase_installedCap!$B$63:$BC$63,assumptions!AJ$2,baseCase_installedCap!$B2:$BC2) -> 447 | AL4: =AVERAGEIF(baseCase_percMembers!$B$63:$BC$63,assumptions!AL$2,baseCase_percMembers!$B2:$BC2) -> 0.002 | AM4: =AVERAGEIF(baseCase_percMembers!$B$63:$BC$63,assumptions!AM$2,baseCase_percMembers!$B2:$BC2) -> 0.002 | AN4: =AVERAGEIF(baseCase_percMembers!$B$63:$BC$63,assumptions!AN$2,baseCase_percMembers!$B2:$BC2) -> 0.002 | AO4: =AVERAGEIF(baseCase_percMembers!$B$63:$BC$63,assumptions!AO$2,baseCase_percMembers!$B2:$BC2) -> 0.002 | AP4: =AVERAGEIF(baseCase_percMembers!$B$63:$BC$63,assumptions!AP$2,baseCase_percMembers!$B2:$BC2) -> 0.002 | AQ4: =AVERAGEIF(baseCase_percMembers!$B$63:$BC$63,assumptions!AQ$2,baseCase_percMembers!$B2:$BC2) -> 0.002 | AR4: =AVERAGEIF(baseCase_percMembers!$B$63:$BC$63,assumptions!AR$2,baseCase_percMembers!$B2:$BC2) -> 0.002 | AS4: =AVERAGEIF(baseCase_percMembers!$B$63:$BC$63,assumptions!AS$2,baseCase_percMembers!$B2:$BC2) -> 0.002 | AT4: =AVERAGEIF(baseCase_percMembers!$B$63:$BC$63,assumptions!AT$2,baseCase_percMembers!$B2:$BC2) -> 0.002
A5: collective learning rate | B5: 0.01 | C5: 0.001 | G5: 2010 | H5: =AVERAGEIF(baseCase_projects!$B$63:$BC$63,assumptions!H$2,baseCase_projects!$B3:$BC3) -> 1 | I5: =AVERAGEIF(baseCase_projects!$B$63:$BC$63,assumptions!I$2,baseCase_projects!$B3:$BC3) -> 1 | J5: =AVERAGEIF(baseCase_projects!$B$63:$BC$63,assumptions!J$2,baseCase_projects!$B3:$BC3) -> 1 | K5: =AVERAGEIF(baseCase_projects!$B$63:$BC$63,assumptions!K$2,baseCase_projects!$B3:$BC3) -> 1 | L5: =AVERAGEIF(baseCase_projects!$B$63:$BC$63,assumptions!L$2,baseCase_projects!$B3:$BC3) -> 1 | M5: =AVERAGEIF(baseCase_projects!$B$63:$BC$63,assumptions!M$2,baseCase_projects!$B3:$BC3) -> 1 | N5: =AVERAGEIF(baseCase_projects!$B$63:$BC$63,assumptions!N$2,baseCase_projects!$B3:$BC3) -> 1 | O5: =AVERAGEIF(baseCase_projects!$B$63:$BC$63,assumptions!O$2,baseCase_projects!$B3:$BC3) -> 1 | P5: =AVERAGEIF(baseCase_projects!$B$63:$BC$63,assumptions!P$2,baseCase_projects!$B3:$BC3) -> 1 | R5: =AVERAGEIF(baseCase_ECs!$B$63:$BC$63,assumptions!R$2,baseCase_ECs!$B3:$BC3) -> 26 | S5: =AVERAGEIF(baseCase_ECs!$B$63:$BC$63,assumptions!S$2,baseCase_ECs!$B3:$BC3) -> 26 | T5: =AVERAGEIF(baseCase_ECs!$B$63:$BC$63,assumptions!T$2,baseCase_ECs!$B3:$BC3) -> 26 | U5: =AVERAGEIF(baseCase_ECs!$B$63:$BC$63,assumptions!U$2,baseCase_ECs!$B3:$BC3) -> 26 | V5: =AVERAGEIF(baseCase_ECs!$B$63:$BC$63,assumptions!V$2,baseCase_ECs!$B3:$BC3) -> 26 | W5: =AVERAGEIF(baseCase_ECs!$B$63:$BC$63,assumptions!W$2,baseCase_ECs!$B3:$BC3) -> 26 | X5: =AVERAGEIF(baseCase_ECs!$B$63:$BC$63,assumptions!X$2,baseCase_ECs!$B3:$BC3) -> 26 | Y5: =AVERAGEIF(baseCase_ECs!$B$63:$BC$63,assumptions!Y$2,baseCase_ECs!$B3:$BC3) -> 26 | Z5: =AVERAGEIF(baseCase_ECs!$B$63:$BC$63,assumptions!Z$2,baseCase_ECs!$B3:$BC3) -> 26 | AB5: =AVERAGEIF(baseCase_installedCap!$B$63:$BC$63,assumptions!AB$2,baseCase_installedCap!$B3:$BC3) -> 447 | AC5: =AVERAGEIF(baseCase_installedCap!$B$63:$BC$63,assumptions!AC$2,baseCase_installedCap!$B3:$BC3) -> 447 | AD5: =AVERAGEIF(baseCase_installedCap!$B$63:$BC$63,assumptions!AD$2,baseCase_installedCap!$B3:$BC3) -> 447 | AE5: =AVERAGEIF(baseCase_installedCap!$B$63:$BC$63,assumptions!AE$2,baseCase_installedCap!$B3:$BC3) -> 447 | AF5: =AVERAGEIF(baseCase_installedCap!$B$63:$BC$63,assumptions!AF$2,baseCase_installedCap!$B3:$BC3) -> 447 | AG5: =AVERAGEIF(baseCase_installedCap!$B$63:$BC$63,assumptions!AG$2,baseCase_installedCap!$B3:$BC3) -> 447 | AH5: =AVERAGEIF(baseCase_installedCap!$B$63:$BC$63,assumptions!AH$2,baseCase_installedCap!$B3:$BC3) -> 447 | AI5: =AVERAGEIF(baseCase_installedCap!$B$63:$BC$63,assumptions!AI$2,baseCase_installedCap!$B3:$BC3) -> 447 | AJ5: =AVERAGEIF(baseCase_installedCap!$B$63:$BC$63,assumptions!AJ$2,baseCase_installedCap!$B3:$BC3) -> 447 | AL5: =AVERAGEIF(baseCase_percMembers!$B$63:$BC$63,assumptions!AL$2,baseCase_percMembers!$B3:$BC3) -> 0.003 | AM5: =AVERAGEIF(baseCase_percMembers!$B$63:$BC$63,assumptions!AM$2,baseCase_percMembers!$B3:$BC3) -> 0.003 | AN5: =AVERAGEIF(baseCase_percMembers!$B$63:$BC$63,assumptions!AN$2,baseCase_percMembers!$B3:$BC3) -> 0.003 | AO5: =AVERAGEIF(baseCase_percMembers!$B$63:$BC$63,assumptions!AO$2,baseCase_percMembers!$B3:$BC3) -> 0.003 | AP5: =AVERAGEIF(baseCase_percMembers!$B$63:$BC$63,assumptions!AP$2,baseCase_percMembers!$B3:$BC3) -> 0.003 | AQ5: =AVERAGEIF(baseCase_percMembers!$B$63:$BC$63,assumptions!AQ$2,baseCase_percMembers!$B3:$BC3) -> 0.003 | AR5: =AVERAGEIF(baseCase_percMembers!$B$63:$BC$63,assumptions!AR$2,baseCase_percMembers!$B3:$BC3) -> 0.003 | AS5: =AVERAGEIF(baseCase_percMembers!$B$63:$BC$63,assumptions!AS$2,baseCase_percMembers!$B3:$BC3) -> 0.003 | AT5: =AVERAGEIF(baseCase_percMembers!$B$63:$BC$63,assumptions!AT$2,baseCase_percMembers!$B3:$BC3) -> 0.003
A6: individual learning rate | B6: 0.025 | C6: 0.05 | G6: 2011 | H6: =AVERAGEIF(baseCase_projects!$B$63:$BC$63,assumptions!H$2,baseCase_projects!$B4:$BC4) -> 46 | I6: =AVERAGEIF(baseCase_projects!$B$63:$BC$63,assumptions!I$2,baseCase_projects!$B4:$BC4) -> 46 | J6: =AVERAGEIF(baseCase_projects!$B$63:$BC$63,assumptions!J$2,baseCase_projects!$B4:$BC4) -> 46 | K6: =AVERAGEIF(baseCase_projects!$B$63:$BC$63,assumptions!K$2,baseCase_projects!$B4:$BC4) -> 46 | L6: =AVERAGEIF(baseCase_projects!$B$63:$BC$63,assumptions!L$2,baseCase_projects!$B4:$BC4) -> 46 | M6: =AVERAGEIF(baseCase_projects!$B$63:$BC$63,assumptions!M$2,baseCase_projects!$B4:$BC4) -> 46 | N6: =AVERAGEIF(baseCase_projects!$B$63:$BC$63,assumptions!N$2,baseCase_projects!$B4:$BC4) -> 46 | O6: =AVERAGEIF(baseCase_projects!$B$63:$BC$63,assumptions!O$2,baseCase_projects!$B4:$BC4) -> 46 | P6: =AVERAGEIF(baseCase_projects!$B$63:$BC$63,assumptions!P$2,baseCase_projects!$B4:$BC4) -> 46 | R6: =AVERAGEIF(baseCase_ECs!$B$63:$BC$63,assumptions!R$2,baseCase_ECs!$B4:$BC4) -> 39 | S6: =AVERAGEIF(baseCase_ECs!$B$63:$BC$63,assumptions!S$2,baseCase_ECs!$B4:$BC4) -> 39 | T6: =AVERAGEIF(baseCase_ECs!$B$63:$BC$63,assumptions!T$2,baseCase_ECs!$B4:$BC4) -> 39 | U6: =AVERAGEIF(baseCase_ECs!$B$63:$BC$63,assumptions!U$2,baseCase_ECs!$B4:$BC4) -> 39 | V6: =AVERAGEIF(baseCase_ECs!$B$63:$BC$63,assumptions!V$2,baseCase_ECs!$B4:$BC4) -> 39 | W6: =AVERAGEIF(baseCase_ECs!$B$63:$BC$63,assumptions!W$2,baseCase_ECs!$B4:$BC4) -> 39 | X6: =AVERAGEIF(baseCase_ECs!$B$63:$BC$63,assumptions!X$2,baseCase_ECs!$B4:$BC4) -> 39 | Y6: =AVERAGEIF(baseCase_ECs!$B$63:$BC$63,assumptions!Y$2,baseCase_ECs!$B4:$BC4) -> 39 | Z6: =AVERAGEIF(baseCase_ECs!$B$63:$BC$63,assumptions!Z$2,baseCase_ECs!$B4:$BC4) -> 39 | AB6: =AVERAGEIF(baseCase_installedCap!$B$63:$BC$63,assumptions!AB$2,baseCase_installedCap!$B4:$BC4) -> 20562 | AC6: =AVERAGEIF(baseCase_installedCap!$B$63:$BC$63,assumptions!AC$2,baseCase_installedCap!$B4:$BC4) -> 20562 | AD6: =AVERAGEIF(baseCase_installedCap!$B$63:$BC$63,assumptions!AD$2,baseCase_installedCap!$B4:$BC4) -> 20562 | AE6: =AVERAGEIF(baseCase_installedCap!$B$63:$BC$63,assumptions!AE$2,baseCase_installedCap!$B4:$BC4) -> 20562 | AF6: =AVERAGEIF(baseCase_installedCap!$B$63:$BC$63,assumptions!AF$2,baseCase_installedCap!$B4:$BC4) -> 20562 | AG6: =AVERAGEIF(baseCase_installedCap!$B$63:$BC$63,assumptions!AG$2,baseCase_installedCap!$B4:$BC4) -> 20562 | AH6: =AVERAGEIF(baseCase_installedCap!$B$63:$BC$63,assumptions!AH$2,baseCase_installedCap!$B4:$BC4) -> 20562 | AI6: =AVERAGEIF(baseCase_installedCap!$B$63:$BC$63,assumptions!AI$2,baseCase_installedCap!$B4:$BC4) -> 20562 | AJ6: =AVERAGEIF(baseCase_installedCap!$B$63:$BC$63,assumptions!AJ$2,baseCase_installedCap!$B4:$BC4) -> 20562 | AL6: =AVERAGEIF(baseCase_percMembers!$B$63:$BC$63,assumptions!AL$2,baseCase_percMembers!$B4:$BC4) -> 0.052 | AM6: =AVERAGEIF(baseCase_percMembers!$B$63:$BC$63,assumptions!AM$2,baseCase_percMembers!$B4:$BC4) -> 0.052 | AN6: =AVERAGEIF(baseCase_percMembers!$B$63:$BC$63,assumptions!AN$2,baseCase_percMembers!$B4:$BC4) -> 0.052 | AO6: =AVERAGEIF(baseCase_percMembers!$B$63:$BC$63,assumptions!AO$2,baseCase_percMembers!$B4:$BC4) -> 0.052 | AP6: =AVERAGEIF(baseCase_percMembers!$B$63:$BC$63,assumptions!AP$2,baseCase_percMembers!$B4:$BC4) -> 0.052 | AQ6: =AVERAGEIF(baseCase_percMembers!$B$63:$BC$63,assumptions!AQ$2,baseCase_percMembers!$B4:$BC4) -> 0.052 | AR6: =AVERAGEIF(baseCase_percMembers!$B$63:$BC$63,assumptions!AR$2,baseCase_percMembers!$B4:$BC4) -> 0.052 | AS6: =AVERAGEIF(baseCase_percMembers!$B$63:$BC$63,assumptions!AS$2,baseCase_percMembers!$B4:$BC4) -> 0.052 | AT6: =AVERAGEIF(baseCase_percMembers!$B$63:$BC$63,assumptions!AT$2,baseCase_percMembers!$B4:$BC4) -> 0.052
A7: network structure | B7: SMALL_SCALE_SIMILAR | C7: SMALL_SCALE_SIMILAR | D7: SMALL_SCALE_SIMILAR | E7: SMALL_SCALE_SIMILAR | G7: 2012 | H7: =AVERAGEIF(baseCase_projects!$B$63:$BC$63,assumptions!H$2,baseCase_projects!$B5:$BC5) -> 53 | I7: =AVERAGEIF(baseCase_projects!$B$63:$BC$63,assumptions!I$2,baseCase_projects!$B5:$BC5) -> 53 | J7: =AVERAGEIF(baseCase_projects!$B$63:$BC$63,assumptions!J$2,baseCase_projects!$B5:$BC5) -> 53 | K7: =AVERAGEIF(baseCase_projects!$B$63:$BC$63,assumptions!K$2,baseCase_projects!$B5:$BC5) -> 53 | L7: =AVERAGEIF(baseCase_projects!$B$63:$BC$63,assumptions!L$2,baseCase_projects!$B5:$BC5) -> 53 | M7: =AVERAGEIF(baseCase_projects!$B$63:$BC$63,assumptions!M$2,baseCase_projects!$B5:$BC5) -> 53 | N7: =AVERAGEIF(baseCase_projects!$B$63:$BC$63,assumptions!N$2,baseCase_projects!$B5:$BC5) -> 53 | O7: =AVERAGEIF(baseCase_projects!$B$63:$BC$63,assumptions!O$2,baseCase_projects!$B5:$BC5) -> 53 | P7: =AVERAGEIF(baseCase_projects!$B$63:$BC$63,assumptions!P$2,baseCase_projects!$B5:$BC5) -> 53 | R7: =AVERAGEIF(baseCase_ECs!$B$63:$BC$63,assumptions!R$2,baseCase_ECs!$B5:$BC5) -> 65 | S7: =AVERAGEIF(baseCase_ECs!$B$63:$BC$63,assumptions!S$2,baseCase_ECs!$B5:$BC5) -> 65 | T7: =AVERAGEIF(baseCase_ECs!$B$63:$BC$63,assumptions!T$2,baseCase_ECs!$B5:$BC5) -> 65 | U7: =AVERAGEIF(baseCase_ECs!$B$63:$BC$63,assumptions!U$2,baseCase_ECs!$B5:$BC5) -> 65 | V7: =AVERAGEIF(baseCase_ECs!$B$63:$BC$63,assumptions!V$2,baseCase_ECs!$B5:$BC5) -> 65 | W7: =AVERAGEIF(baseCase_ECs!$B$63:$BC$63,assumptions!W$2,baseCase_ECs!$B5:$BC5) -> 65 | X7: =AVERAGEIF(baseCase_ECs!$B$63:$BC$63,assumptions!X$2,baseCase_ECs!$B5:$BC5) -> 65 | Y7: =AVERAGEIF(baseCase_ECs!$B$63:$BC$63,assumptions!Y$2,baseCase_ECs!$B5:$BC5) -> 65 | Z7: =AVERAGEIF(baseCase_ECs!$B$63:$BC$63,assumptions!Z$2,baseCase_ECs!$B5:$BC5) -> 65 | AB7: =AVERAGEIF(baseCase_installedCap!$B$63:$BC$63,assumptions!AB$2,baseCase_installedCap!$B5:$BC5) -> 23691 | AC7: =AVERAGEIF(baseCase_installedCap!$B$63:$BC$63,assumptions!AC$2,baseCase_installedCap!$B5:$BC5) -> 23691 | AD7: =AVERAGEIF(baseCase_installedCap!$B$63:$BC$63,assumptions!AD$2,baseCase_installedCap!$B5:$BC5) -> 23691 | AE7: =AVERAGEIF(baseCase_installedCap!$B$63:$BC$63,assumptions!AE$2,baseCase_installedCap!$B5:$BC5) -> 23691 | AF7: =AVERAGEIF(baseCase_installedCap!$B$63:$BC$63,assumptions!AF$2,baseCase_installedCap!$B5:$BC5) -> 23691 | AG7: =AVERAGEIF(baseCase_installedCap!$B$63:$BC$63,assumptions!AG$2,baseCase_installedCap!$B5:$BC5) -> 23691 | AH7: =AVERAGEIF(baseCase_installedCap!$B$63:$BC$63,assumptions!AH$2,baseCase_installedCap!$B5:$BC5) -> 23691 | AI7: =AVERAGEIF(baseCase_installedCap!$B$63:$BC$63,assumptions!AI$2,baseCase_installedCap!$B5:$BC5) -> 23691 | AJ7: =AVERAGEIF(baseCase_installedCap!$B$63:$BC$63,assumptions!AJ$2,baseCase_installedCap!$B5:$BC5) -> 23691 | AL7: =AVERAGEIF(baseCase_percMembers!$B$63:$BC$63,assumptions!AL$2,baseCase_percMembers!$B5:$BC5) -> 0.061 | AM7: =AVERAGEIF(baseCase_percMembers!$B$63:$BC$63,assumptions!AM$2,baseCase_percMembers!$B5:$BC5) -> 0.061 | AN7: =AVERAGEIF(baseCase_percMembers!$B$63:$BC$63,assumptions!AN$2,baseCase_percMembers!$B5:$BC5) -> 0.061 | AO7: =AVERAGEIF(baseCase_percMembers!$B$63:$BC$63,assumptions!AO$2,baseCase_percMembers!$B5:$BC5) -> 0.061 | AP7: =AVERAGEIF(baseCase_percMembers!$B$63:$BC$63,assumptions!AP$2,baseCase_percMembers!$B5:$BC5) -> 0.061 | AQ7: =AVERAGEIF(baseCase_percMembers!$B$63:$BC$63,assumptions!AQ$2,baseCase_percMembers!$B5:$BC5) -> 0.061 | AR7: =AVERAGEIF(baseCase_percMembers!$B$63:$BC$63,assumptions!AR$2,baseCase_percMembers!$B5:$BC5) -> 0.061 | AS7: =AVERAGEIF(baseCase_percMembers!$B$63:$BC$63,assumptions!AS$2,baseCase_percMembers!$B5:$BC5) -> 0.061 | AT7: =AVERAGEIF(baseCase_percMembers!$B$63:$BC$63,assumptions!AT$2,baseCase_percMembers!$B5:$BC5) -> 0.061
G8: 2013 | H8: =AVERAGEIF(baseCase_projects!$B$63:$BC$63,assumptions!H$2,baseCase_projects!$B6:$BC6) -> 72 | I8: =AVERAGEIF(baseCase_projects!$B$63:$BC$63,assumptions!I$2,baseCase_projects!$B6:$BC6) -> 72 | J8: =AVERAGEIF(baseCase_projects!$B$63:$BC$63,assumptions!J$2,baseCase_projects!$B6:$BC6) -> 72 | K8: =AVERAGEIF(baseCase_projects!$B$63:$BC$63,assumptions!K$2,baseCase_projects!$B6:$BC6) -> 72 | L8: =AVERAGEIF(baseCase_projects!$B$63:$BC$63,assumptions!L$2,baseCase_projects!$B6:$BC6) -> 72 | M8: =AVERAGEIF(baseCase_projects!$B$63:$BC$63,assumptions!M$2,baseCase_projects!$B6:$BC6) -> 72 | N8: =AVERAGEIF(baseCase_projects!$B$63:$BC$63,assumptions!N$2,baseCase_projects!$B6:$BC6) -> 72 | O8: =AVERAGEIF(baseCase_projects!$B$63:$BC$63,assumptions!O$2,baseCase_projects!$B6:$BC6) -> 72 | P8: =AVERAGEIF(baseCase_projects!$B$63:$BC$63,assumptions!P$2,baseCase_projects!$B6:$BC6) -> 72 | R8: =AVERAGEIF(baseCase_ECs!$B$63:$BC$63,assumptions!R$2,baseCase_ECs!$B6:$BC6) -> 123 | S8: =AVERAGEIF(baseCase_ECs!$B$63:$BC$63,assumptions!S$2,baseCase_ECs!$B6:$BC6) -> 123 | T8: =AVERAGEIF(baseCase_ECs!$B$63:$BC$63,assumptions!T$2,baseCase_ECs!$B6:$BC6) -> 123 | U8: =AVERAGEIF(baseCase_ECs!$B$63:$BC$63,assumptions!U$2,baseCase_ECs!$B6:$BC6) -> 123 | V8: =AVERAGEIF(baseCase_ECs!$B$63:$BC$63,assumptions!V$2,baseCase_ECs!$B6:$BC6) -> 123 | W8: =AVERAGEIF(baseCase_ECs!$B$63:$BC$63,assumptions!W$2,baseCase_ECs!$B6:$BC6) -> 123 | X8: =AVERAGEIF(baseCase_ECs!$B$63:$BC$63,assumptions!X$2,baseCase_ECs!$B6:$BC6) -> 123 | Y8: =AVERAGEIF(baseCase_ECs!$B$63:$BC$63,assumptions!Y$2,baseCase_ECs!$B6:$BC6) -> 123 | Z8: =AVERAGEIF(baseCase_ECs!$B$63:$BC$63,assumptions!Z$2,baseCase_ECs!$B6:$BC6) -> 123 | AB8: =AVERAGEIF(baseCase_installedCap!$B$63:$BC$63,assumptions!AB$2,baseCase_installedCap!$B6:$BC6) -> 32184 | AC8: =AVERAGEIF(baseCase_installedCap!$B$63:$BC$63,assumptions!AC$2,baseCase_installedCap!$B6:$BC6) -> 32184 | AD8: =AVERAGEIF(baseCase_installedCap!$B$63:$BC$63,assumptions!AD$2,baseCase_installedCap!$B6:$BC6) -> 32184 | AE8: =AVERAGEIF(baseCase_installedCap!$B$63:$BC$63,assumptions!AE$2,baseCase_installedCap!$B6:$BC6) -> 32184 | AF8: =AVERAGEIF(baseCase_installedCap!$B$63:$BC$63,assumptions!AF$2,baseCase_installedCap!$B6:$BC6) -> 32184 | AG8: =AVERAGEIF(baseCase_installedCap!$B$63:$BC$63,assumptions!AG$2,baseCase_installedCap!$B6:$BC6) -> 32184 | AH8: =AVERAGEIF(baseCase_installedCap!$B$63:$BC$63,assumptions!AH$2,baseCase_installedCap!$B6:$BC6) -> 32184 | AI8: =AVERAGEIF(baseCase_installedCap!$B$63:$BC$63,assumptions!AI$2,baseCase_installedCap!$B6:$BC6) -> 32184 | AJ8: =AVERAGEIF(baseCase_installedCap!$B$63:$BC$63,assumptions!AJ$2,baseCase_installedCap!$B6:$BC6) -> 32184 | AL8: =AVERAGEIF(baseCase_percMembers!$B$63:$BC$63,assumptions!AL$2,baseCase_percMembers!$B6:$BC6) -> 0.084 | AM8: =AVERAGEIF(baseCase_percMembers!$B$63:$BC$63,assumptions!AM$2,baseCase_percMembers!$B6:$BC6) -> 0.084 | AN8: =AVERAGEIF(baseCase_percMembers!$B$63:$BC$63,assumptions!AN$2,baseCase_percMembers!$B6:$BC6) -> 0.084 | AO8: =AVERAGEIF(baseCase_percMembers!$B$63:$BC$63,assumptions!AO$2,baseCase_percMembers!$B6:$BC6) -> 0.084 | AP8: =AVERAGEIF(baseCase_percMembers!$B$63:$BC$63,assumptions!AP$2,baseCase_percMembers!$B6:$BC6) -> 0.084 | AQ8: =AVERAGEIF(baseCase_percMembers!$B$63:$BC$63,assumptions!AQ$2,baseCase_percMembers!$B6:$BC6) -> 0.084 | AR8: =AVERAGEIF(baseCase_percMembers!$B$63:$BC$63,assumptions!AR$2,baseCase_percMembers!$B6:$BC6) -> 0.084 | AS8: =AVERAGEIF(baseCase_percMembers!$B$63:$BC$63,assumptions!AS$2,baseCase_percMembers!$B6:$BC6) -> 0.084 | AT8: =AVERAGEIF(baseCase_percMembers!$B$63:$BC$63,assumptions!AT$2,baseCase_percMembers!$B6:$BC6) -> 0.084
G9: 2014 | H9: =AVERAGEIF(baseCase_projects!$B$63:$BC$63,assumptions!H$2,baseCase_projects!$B7:$BC7) -> 100 | I9: =AVERAGEIF(baseCase_projects!$B$63:$BC$63,assumptions!I$2,baseCase_projects!$B7:$BC7) -> 100 | J9: =AVERAGEIF(baseCase_projects!$B$63:$BC$63,assumptions!J$2,baseCase_projects!$B7:$BC7) -> 100 | K9: =AVERAGEIF(baseCase_projects!$B$63:$BC$63,assumptions!K$2,baseCase_projects!$B7:$BC7) -> 100 | L9: =AVERAGEIF(baseCase_projects!$B$63:$BC$63,assumptions!L$2,baseCase_projects!$B7:$BC7) -> 100 | M9: =AVERAGEIF(baseCase_projects!$B$63:$BC$63,assumptions!M$2,baseCase_projects!$B7:$BC7) -> 100 | N9: =AVERAGEIF(baseCase_projects!$B$63:$BC$63,assumptions!N$2,baseCase_projects!$B7:$BC7) -> 100 | O9: =AVERAGEIF(baseCase_projects!$B$63:$BC$63,assumptions!O$2,baseCase_projects!$B7:$BC7) -> 100 | P9: =AVERAGEIF(baseCase_projects!$B$63:$BC$63,assumptions!P$2,baseCase_projects!$B7:$BC7) -> 100 | R9: =AVERAGEIF(baseCase_ECs!$B$63:$BC$63,assumptions!R$2,baseCase_ECs!$B7:$BC7) -> 176 | S9: =AVERAGEIF(baseCase_ECs!$B$63:$BC$63,assumptions!S$2,baseCase_ECs!$B7:$BC7) -> 176 | T9: =AVERAGEIF(baseCase_ECs!$B$63:$BC$63,assumptions!T$2,baseCase_ECs!$B7:$BC7) -> 176 | U9: =AVERAGEIF(baseCase_ECs!$B$63:$BC$63,assumptions!U$2,baseCase_ECs!$B7:$BC7) -> 176 | V9: =AVERAGEIF(baseCase_ECs!$B$63:$BC$63,assumptions!V$2,baseCase_ECs!$B7:$BC7) -> 176 | W9: =AVERAGEIF(baseCase_ECs!$B$63:$BC$63,assumptions!W$2,baseCase_ECs!$B7:$BC7) -> 176 | X9: =AVERAGEIF(baseCase_ECs!$B$63:$BC$63,assumptions!X$2,baseCase_ECs!$B7:$BC7) -> 176 | Y9: =AVERAGEIF(baseCase_ECs!$B$63:$BC$63,assumptions!Y$2,baseCase_ECs!$B7:$BC7) -> 176 | Z9: =AVERAGEIF(baseCase_ECs!$B$63:$BC$63,assumptions!Z$2,baseCase_ECs!$B7:$BC7) -> 176 | AB9: =AVERAGEIF(baseCase_installedCap!$B$63:$BC$63,assumptions!AB$2,baseCase_installedCap!$B7:$BC7) -> 44700 | AC9: =AVERAGEIF(baseCase_installedCap!$B$63:$BC$63,assumptions!AC$2,baseCase_installedCap!$B7:$BC7) -> 44700 | AD9: =AVERAGEIF(baseCase_installedCap!$B$63:$BC$63,assumptions!AD$2,baseCase_installedCap!$B7:$BC7) -> 44700 | AE9: =AVERAGEIF(baseCase_installedCap!$B$63:$BC$63,assumptions!AE$2,baseCase_installedCap!$B7:$BC7) -> 44700 | AF9: =AVERAGEIF(baseCase_installedCap!$B$63:$BC$63,assumptions!AF$2,baseCase_installedCap!$B7:$BC7) -> 44700 | AG9: =AVERAGEIF(baseCase_installedCap!$B$63:$BC$63,assumptions!AG$2,baseCase_installedCap!$B7:$BC7) -> 44700 | AH9: =AVERAGEIF(baseCase_installedCap!$B$63:$BC$63,assumptions!AH$2,baseCase_installedCap!$B7:$BC7) -> 44700 | AI9: =AVERAGEIF(baseCase_installedCap!$B$63:$BC$63,assumptions!AI$2,baseCase_installedCap!$B7:$BC7) -> 44700 | AJ9: =AVERAGEIF(baseCase_installedCap!$B$63:$BC$63,assumptions!AJ$2,baseCase_installedCap!$B7:$BC7) -> 44700 | AL9: =AVERAGEIF(baseCase_percMembers!$B$63:$BC$63,assumptions!AL$2,baseCase_percMembers!$B7:$BC7) -> 0.117 | AM9: =AVERAGEIF(baseCase_percMembers!$B$63:$BC$63,assumptions!AM$2,baseCase_percMembers!$B7:$BC7) -> 0.117 | AN9: =AVERAGEIF(baseCase_percMembers!$B$63:$BC$63,assumptions!AN$2,baseCase_percMembers!$B7:$BC7) -> 0.117 | AO9: =AVERAGEIF(baseCase_percMembers!$B$63:$BC$63,assumptions!AO$2,baseCase_percMembers!$B7:$BC7) -> 0.117 | AP9: =AVERAGEIF(baseCase_percMembers!$B$63:$BC$63,assumptions!AP$2,baseCase_percMembers!$B7:$BC7) -> 0.117 | AQ9: =AVERAGEIF(baseCase_percMembers!$B$63:$BC$63,assumptions!AQ$2,baseCase_percMembers!$B7:$BC7) -> 0.117 | AR9: =AVERAGEIF(baseCase_percMembers!$B$63:$BC$63,assumptions!AR$2,baseCase_percMembers!$B7:$BC7) -> 0.117 | AS9: =AVERAGEIF(baseCase_percMembers!$B$63:$BC$63,assumptions!AS$2,baseCase_percMembers!$B7:$BC7) -> 0.117 | AT9: =AVERAGEIF(baseCase_percMembers!$B$63:$BC$63,assumptions!AT$2,baseCase_percMembers!$B7:$BC7) -> 0.117
G10: 2015 | H10: =AVERAGEIF(baseCase_projects!$B$63:$BC$63,assumptions!H$2,baseCase_projects!$B8:$BC8) -> 153 | I10: =AVERAGEIF(baseCase_projects!$B$63:$BC$63,assumptions!I$2,baseCase_projects!$B8:$BC8) -> 153 | J10: =AVERAGEIF(baseCase_projects!$B$63:$BC$63,assumptions!J$2,baseCase_projects!$B8:$BC8) -> 153 | K10: =AVERAGEIF(baseCase_projects!$B$63:$BC$63,assumptions!K$2,baseCase_projects!$B8:$BC8) -> 153 | L10: =AVERAGEIF(baseCase_projects!$B$63:$BC$63,assumptions!L$2,baseCase_projects!$B8:$BC8) -> 153 | M10: =AVERAGEIF(baseCase_projects!$B$63:$BC$63,assumptions!M$2,baseCase_projects!$B8:$BC8) -> 153 | N10: =AVERAGEIF(baseCase_projects!$B$63:$BC$63,assumptions!N$2,baseCase_projects!$B8:$BC8) -> 153 | O10: =AVERAGEIF(baseCase_projects!$B$63:$BC$63,assumptions!O$2,baseCase_projects!$B8:$BC8) -> 153 | P10: =AVERAGEIF(baseCase_projects!$B$63:$BC$63,assumptions!P$2,baseCase_projects!$B8:$BC8) -> 153 | R10: =AVERAGEIF(baseCase_ECs!$B$63:$BC$63,assumptions!R$2,baseCase_ECs!$B8:$BC8) -> 237 | S10: =AVERAGEIF(baseCase_ECs!$B$63:$BC$63,assumptions!S$2,baseCase_ECs!$B8:$BC8) -> 237 | T10: =AVERAGEIF(baseCase_ECs!$B$63:$BC$63,assumptions!T$2,baseCase_ECs!$B8:$BC8) -> 237 | U10: =AVERAGEIF(baseCase_ECs!$B$63:$BC$63,assumptions!U$2,baseCase_ECs!$B8:$BC8) -> 237 | V10: =AVERAGEIF(baseCase_ECs!$B$63:$BC$63,assumptions!V$2,baseCase_ECs!$B8:$BC8) -> 237 | W10: =AVERAGEIF(baseCase_ECs!$B$63:$BC$63,assumptions!W$2,baseCase_ECs!$B8:$BC8) -> 237 | X10: =AVERAGEIF(baseCase_ECs!$B$63:$BC$63,assumptions!X$2,baseCase_ECs!$B8:$BC8) -> 237 | Y10: =AVERAGEIF(baseCase_ECs!$B$63:$BC$63,assumptions!Y$2,baseCase_ECs!$B8:$BC8) -> 237 | Z10: =AVERAGEIF(baseCase_ECs!$B$63:$BC$63,assumptions!Z$2,baseCase_ECs!$B8:$BC8) -> 237 | AB10: =AVERAGEIF(baseCase_installedCap!$B$63:$BC$63,assumptions!AB$2,baseCase_installedCap!$B8:$BC8) -> 68391 | AC10: =AVERAGEIF(baseCase_installedCap!$B$63:$BC$63,assumptions!AC$2,baseCase_installedCap!$B8:$BC8) -> 68391 | AD10: =AVERAGEIF(baseCase_installedCap!$B$63:$BC$63,assumptions!AD$2,baseCase_installedCap!$B8:$BC8) -> 68391 | AE10: =AVERAGEIF(baseCase_installedCap!$B$63:$BC$63,assumptions!AE$2,baseCase_installedCap!$B8:$BC8) -> 68391 | AF10: =AVERAGEIF(baseCase_installedCap!$B$63:$BC$63,assumptions!AF$2,baseCase_installedCap!$B8:$BC8) -> 68391 | AG10: =AVERAGEIF(baseCase_installedCap!$B$63:$BC$63,assumptions!AG$2,baseCase_installedCap!$B8:$BC8) -> 68391 | AH10: =AVERAGEIF(baseCase_installedCap!$B$63:$BC$63,assumptions!AH$2,baseCase_installedCap!$B8:$BC8) -> 68391 | AI10: =AVERAGEIF(baseCase_installedCap!$B$63:$BC$63,assumptions!AI$2,baseCase_installedCap!$B8:$BC8) -> 68391 | AJ10: =AVERAGEIF(baseCase_installedCap!$B$63:$BC$63,assumptions!AJ$2,baseCase_installedCap!$B8:$BC8) -> 68391 | AL10: =AVERAGEIF(baseCase_percMembers!$B$63:$BC$63,assumptions!AL$2,baseCase_percMembers!$B8:$BC8) -> 0.178 | AM10: =AVERAGEIF(baseCase_percMembers!$B$63:$BC$63,assumptions!AM$2,baseCase_percMembers!$B8:$BC8) -> 0.178 | AN10: =AVERAGEIF(baseCase_percMembers!$B$63:$BC$63,assumptions!AN$2,baseCase_percMembers!$B8:$BC8) -> 0.178 | AO10: =AVERAGEIF(baseCase_percMembers!$B$63:$BC$63,assumptions!AO$2,baseCase_percMembers!$B8:$BC8) -> 0.178 | AP10: =AVERAGEIF(baseCase_percMembers!$B$63:$BC$63,assumptions!AP$2,baseCase_percMembers!$B8:$BC8) -> 0.178 | AQ10: =AVERAGEIF(baseCase_percMembers!$B$63:$BC$63,assumptions!AQ$2,baseCase_percMembers!$B8:$BC8) -> 0.178 | AR10: =AVERAGEIF(baseCase_percMembers!$B$63:$BC$63,assumptions!AR$2,baseCase_percMembers!$B8:$BC8) -> 0.178 | AS10: =AVERAGEIF(baseCase_percMembers!$B$63:$BC$63,assumptions!AS$2,baseCase_percMembers!$B8:$BC8) -> 0.178 | AT10: =AVERAGEIF(baseCase_percMembers!$B$63:$BC$63,assumptions!AT$2,baseCase_percMembers!$B8:$BC8) -> 0.178
G11: 2016 | H11: =AVERAGEIF(baseCase_projects!$B$63:$BC$63,assumptions!H$2,baseCase_projects!$B9:$BC9) -> 226 | I11: =AVERAGEIF(baseCase_projects!$B$63:$BC$63,assumptions!I$2,baseCase_projects!$B9:$BC9) -> 226 | J11: =AVERAGEIF(baseCase_projects!$B$63:$BC$63,assumptions!J$2,baseCase_projects!$B9:$BC9) -> 226 | K11: =AVERAGEIF(baseCase_projects!$B$63:$BC$63,assumptions!K$2,baseCase_projects!$B9:$BC9) -> 226 | L11: =AVERAGEIF(baseCase_projects!$B$63:$BC$63,assumptions!L$2,baseCase_projects!$B9:$BC9) -> 226 | M11: =AVERAGEIF(baseCase_projects!$B$63:$BC$63,assumptions!M$2,baseCase_projects!$B9:$BC9) -> 226 | N11: =AVERAGEIF(baseCase_projects!$B$63:$BC$63,assumptions!N$2,baseCase_projects!$B9:$BC9) -> 226 | O11: =AVERAGEIF(baseCase_projects!$B$63:$BC$63,assumptions!O$2,baseCase_projects!$B9:$BC9) -> 226 | P11: =AVERAGEIF(baseCase_projects!$B$63:$BC$63,assumptions!P$2,baseCase_projects!$B9:$BC9) -> 226 | R11: =AVERAGEIF(baseCase_ECs!$B$63:$BC$63,assumptions!R$2,baseCase_ECs!$B9:$BC9) -> 304 | S11: =AVERAGEIF(baseCase_ECs!$B$63:$BC$63,assumptions!S$2,baseCase_ECs!$B9:$BC9) -> 304 | T11: =AVERAGEIF(baseCase_ECs!$B$63:$BC$63,assumptions!T$2,baseCase_ECs!$B9:$BC9) -> 304 | U11: =AVERAGEIF(baseCase_ECs!$B$63:$BC$63,assumptions!U$2,baseCase_ECs!$B9:$BC9) -> 304 | V11: =AVERAGEIF(baseCase_ECs!$B$63:$BC$63,assumptions!V$2,baseCase_ECs!$B9:$BC9) -> 304 | W11: =AVERAGEIF(baseCase_ECs!$B$63:$BC$63,assumptions!W$2,baseCase_ECs!$B9:$BC9) -> 304 | X11: =AVERAGEIF(baseCase_ECs!$B$63:$BC$63,assumptions!X$2,baseCase_ECs!$B9:$BC9) -> 304 | Y11: =AVERAGEIF(baseCase_ECs!$B$63:$BC$63,assumptions!Y$2,baseCase_ECs!$B9:$BC9) -> 304 | Z11: =AVERAGEIF(baseCase_ECs!$B$63:$BC$63,assumptions!Z$2,baseCase_ECs!$B9:$BC9) -> 304 | AB11: =AVERAGEIF(baseCase_installedCap!$B$63:$BC$63,assumptions!AB$2,baseCase_installedCap!$B9:$BC9) -> 101022 | AC11: =AVERAGEIF(baseCase_installedCap!$B$63:$BC$63,assumptions!AC$2,baseCase_installedCap!$B9:$BC9) -> 101022 | AD11: =AVERAGEIF(baseCase_installedCap!$B$63:$BC$63,assumptions!AD$2,baseCase_installedCap!$B9:$BC9) -> 101022 | AE11: =AVERAGEIF(baseCase_installedCap!$B$63:$BC$63,assumptions!AE$2,baseCase_installedCap!$B9:$BC9) -> 101022 | AF11: =AVERAGEIF(baseCase_installedCap!$B$63:$BC$63,assumptions!AF$2,baseCase_installedCap!$B9:$BC9) -> 101022 | AG11: =AVERAGEIF(baseCase_installedCap!$B$63:$BC$63,assumptions!AG$2,baseCase_installedCap!$B9:$BC9) -> 101022 | AH11: =AVERAGEIF(baseCase_installedCap!$B$63:$BC$63,assumptions!AH$2,baseCase_installedCap!$B9:$BC9) -> 101022 | AI11: =AVERAGEIF(baseCase_installedCap!$B$63:$BC$63,assumptions!AI$2,baseCase_installedCap!$B9:$BC9) -> 101022 | AJ11: =AVERAGEIF(baseCase_installedCap!$B$63:$BC$63,assumptions!AJ$2,baseCase_installedCap!$B9:$BC9) -> 101022 | AL11: =AVERAGEIF(baseCase_percMembers!$B$63:$BC$63,assumptions!AL$2,baseCase_percMembers!$B9:$BC9) -> 0.259 | AM11: =AVERAGEIF(baseCase_percMembers!$B$63:$BC$63,assumptions!AM$2,baseCase_percMembers!$B9:$BC9) -> 0.259 | AN11: =AVERAGEIF(baseCase_percMembers!$B$63:$BC$63,assumptions!AN$2,baseCase_percMembers!$B9:$BC9) -> 0.259 | AO11: =AVERAGEIF(baseCase_percMembers!$B$63:$BC$63,assumptions!AO$2,baseCase_percMembers!$B9:$BC9) -> 0.259 | AP11: =AVERAGEIF(baseCase_percMembers!$B$63:$BC$63,assumptions!AP$2,baseCase_percMembers!$B9:$BC9) -> 0.259 | AQ11: =AVERAGEIF(baseCase_percMembers!$B$63:$BC$63,assumptions!AQ$2,baseCase_percMembers!$B9:$BC9) -> 0.259 | AR11: =AVERAGEIF(baseCase_percMembers!$B$63:$BC$63,assumptions!AR$2,baseCase_percMembers!$B9:$BC9) -> 0.259 | AS11: =AVERAGEIF(baseCase_percMembers!$B$63:$BC$63,assumptions!AS$2,baseCase_percMembers!$B9:$BC9) -> 0.259 | AT11: =AVERAGEIF(baseCase_percMembers!$B$63:$BC$63,assumptions!AT$2,baseCase_percMembers!$B9:$BC9) -> 0.259
G12: 2017 | H12: =AVERAGEIF(baseCase_projects!$B$63:$BC$63,assumptions!H$2,baseCase_projects!$B10:$BC10) -> 336 | I12: =AVERAGEIF(baseCase_projects!$B$63:$BC$63,assumptions!I$2,baseCase_projects!$B10:$BC10) -> 336 | J12: =AVERAGEIF(baseCase_projects!$B$63:$BC$63,assumptions!J$2,baseCase_projects!$B10:$BC10) -> 336 | K12: =AVERAGEIF(baseCase_projects!$B$63:$BC$63,assumptions!K$2,baseCase_projects!$B10:$BC10) -> 336 | L12: =AVERAGEIF(baseCase_projects!$B$63:$BC$63,assumptions!L$2,baseCase_projects!$B10:$BC10) -> 336 | M12: =AVERAGEIF(baseCase_projects!$B$63:$BC$63,assumptions!M$2,baseCase_projects!$B10:$BC10) -> 336 | N12: =AVERAGEIF(baseCase_projects!$B$63:$BC$63,assumptions!N$2,baseCase_projects!$B10:$BC10) -> 336 | O12: =AVERAGEIF(baseCase_projects!$B$63:$BC$63,assumptions!O$2,baseCase_projects!$B10:$BC10) -> 336 | P12: =AVERAGEIF(baseCase_projects!$B$63:$BC$63,assumptions!P$2,baseCase_projects!$B10:$BC10) -> 336 | R12: =AVERAGEIF(baseCase_ECs!$B$63:$BC$63,assumptions!R$2,baseCase_ECs!$B10:$BC10) -> 382 | S12: =AVERAGEIF(baseCase_ECs!$B$63:$BC$63,assumptions!S$2,baseCase_ECs!$B10:$BC10) -> 382 | T12: =AVERAGEIF(baseCase_ECs!$B$63:$BC$63,assumptions!T$2,baseCase_ECs!$B10:$BC10) -> 382 | U12: =AVERAGEIF(baseCase_ECs!$B$63:$BC$63,assumptions!U$2,baseCase_ECs!$B10:$BC10) -> 382 | V12: =AVERAGEIF(baseCase_ECs!$B$63:$BC$63,assumptions!V$2,baseCase_ECs!$B10:$BC10) -> 382 | W12: =AVERAGEIF(baseCase_ECs!$B$63:$BC$63,assumptions!W$2,baseCase_ECs!$B10:$BC10) -> 382 | X12: =AVERAGEIF(baseCase_ECs!$B$63:$BC$63,assumptions!X$2,baseCase_ECs!$B10:$BC10) -> 382 | Y12: =AVERAGEIF(baseCase_ECs!$B$63:$BC$63,assumptions!Y$2,baseCase_ECs!$B10:$BC10) -> 382 | Z12: =AVERAGEIF(baseCase_ECs!$B$63:$BC$63,assumptions!Z$2,baseCase_ECs!$B10:$BC10) -> 382 | AB12: =AVERAGEIF(baseCase_installedCap!$B$63:$BC$63,assumptions!AB$2,baseCase_installedCap!$B10:$BC10) -> 150192 | AC12: =AVERAGEIF(baseCase_installedCap!$B$63:$BC$63,assumptions!AC$2,baseCase_installedCap!$B10:$BC10) -> 150192 | AD12: =AVERAGEIF(baseCase_installedCap!$B$63:$BC$63,assumptions!AD$2,baseCase_installedCap!$B10:$BC10) -> 150192 | AE12: =AVERAGEIF(baseCase_installedCap!$B$63:$BC$63,assumptions!AE$2,baseCase_installedCap!$B10:$BC10) -> 150192 | AF12: =AVERAGEIF(baseCase_installedCap!$B$63:$BC$63,assumptions!AF$2,baseCase_installedCap!$B10:$BC10) -> 150192 | AG12: =AVERAGEIF(baseCase_installedCap!$B$63:$BC$63,assumptions!AG$2,baseCase_installedCap!$B10:$BC10) -> 150192 | AH12: =AVERAGEIF(baseCase_installedCap!$B$63:$BC$63,assumptions!AH$2,baseCase_installedCap!$B10:$BC10) -> 150192 | AI12: =AVERAGEIF(baseCase_installedCap!$B$63:$BC$63,assumptions!AI$2,baseCase_installedCap!$B10:$BC10) -> 150192 | AJ12: =AVERAGEIF(baseCase_installedCap!$B$63:$BC$63,assumptions!AJ$2,baseCase_installedCap!$B10:$BC10) -> 150192 | AL12: =AVERAGEIF(baseCase_percMembers!$B$63:$BC$63,assumptions!AL$2,baseCase_percMembers!$B10:$BC10) -> 0.381 | AM12: =AVERAGEIF(baseCase_percMembers!$B$63:$BC$63,assumptions!AM$2,baseCase_percMembers!$B10:$BC10) -> 0.381 | AN12: =AVERAGEIF(baseCase_percMembers!$B$63:$BC$63,assumptions!AN$2,baseCase_percMembers!$B10:$BC10) -> 0.381 | AO12: =AVERAGEIF(baseCase_percMembers!$B$63:$BC$63,assumptions!AO$2,baseCase_percMembers!$B10:$BC10) -> 0.381 | AP12: =AVERAGEIF(baseCase_percMembers!$B$63:$BC$63,assumptions!AP$2,baseCase_percMembers!$B10:$BC10) -> 0.381 | AQ12: =AVERAGEIF(baseCase_percMembers!$B$63:$BC$63,assumptions!AQ$2,baseCase_percMembers!$B10:$BC10) -> 0.381 | AR12: =AVERAGEIF(baseCase_percMembers!$B$63:$BC$63,assumptions!AR$2,baseCase_percMembers!$B10:$BC10) -> 0.381 | AS12: =AVERAGEIF(baseCase_percMembers!$B$63:$BC$63,assumptions!AS$2,baseCase_percMembers!$B10:$BC10) -> 0.381 | AT12: =AVERAGEIF(baseCase_percMembers!$B$63:$BC$63,assumptions!AT$2,baseCase_percMembers!$B10:$BC10) -> 0.381
G13: 2018 | H13: =AVERAGEIF(baseCase_projects!$B$63:$BC$63,assumptions!H$2,baseCase_projects!$B11:$BC11) -> 524 | I13: =AVERAGEIF(baseCase_projects!$B$63:$BC$63,assumptions!I$2,baseCase_projects!$B11:$BC11) -> 524 | J13: =AVERAGEIF(baseCase_projects!$B$63:$BC$63,assumptions!J$2,baseCase_projects!$B11:$BC11) -> 524 | K13: =AVERAGEIF(baseCase_projects!$B$63:$BC$63,assumptions!K$2,baseCase_projects!$B11:$BC11) -> 524 | L13: =AVERAGEIF(baseCase_projects!$B$63:$BC$63,assumptions!L$2,baseCase_projects!$B11:$BC11) -> 524 | M13: =AVERAGEIF(baseCase_projects!$B$63:$BC$63,assumptions!M$2,baseCase_projects!$B11:$BC11) -> 524 | N13: =AVERAGEIF(baseCase_projects!$B$63:$BC$63,assumptions!N$2,baseCase_projects!$B11:$BC11) -> 524 | O13: =AVERAGEIF(baseCase_projects!$B$63:$BC$63,assumptions!O$2,baseCase_projects!$B11:$BC11) -> 524 | P13: =AVERAGEIF(baseCase_projects!$B$63:$BC$63,assumptions!P$2,baseCase_projects!$B11:$BC11) -> 524 | R13: =AVERAGEIF(baseCase_ECs!$B$63:$BC$63,assumptions!R$2,baseCase_ECs!$B11:$BC11) -> 476 | S13: =AVERAGEIF(baseCase_ECs!$B$63:$BC$63,assumptions!S$2,baseCase_ECs!$B11:$BC11) -> 476 | T13: =AVERAGEIF(baseCase_ECs!$B$63:$BC$63,assumptions!T$2,baseCase_ECs!$B11:$BC11) -> 476 | U13: =AVERAGEIF(baseCase_ECs!$B$63:$BC$63,assumptions!U$2,baseCase_ECs!$B11:$BC11) -> 476 | V13: =AVERAGEIF(baseCase_ECs!$B$63:$BC$63,assumptions!V$2,baseCase_ECs!$B11:$BC11) -> 476 | W13: =AVERAGEIF(baseCase_ECs!$B$63:$BC$63,assumptions!W$2,baseCase_ECs!$B11:$BC11) -> 476 | X13: =AVERAGEIF(baseCase_ECs!$B$63:$BC$63,assumptions!X$2,baseCase_ECs!$B11:$BC11) -> 476 | Y13: =AVERAGEIF(baseCase_ECs!$B$63:$BC$63,assumptions!Y$2,baseCase_ECs!$B11:$BC11) -> 476 | Z13: =AVERAGEIF(baseCase_ECs!$B$63:$BC$63,assumptions!Z$2,baseCase_ECs!$B11:$BC11) -> 476 | AB13: =AVERAGEIF(baseCase_installedCap!$B$63:$BC$63,assumptions!AB$2,baseCase_installedCap!$B11:$BC11) -> 234228 | AC13: =AVERAGEIF(baseCase_installedCap!$B$63:$BC$63,assumptions!AC$2,baseCase_installedCap!$B11:$BC11) -> 234228 | AD13: =AVERAGEIF(baseCase_installedCap!$B$63:$BC$63,assumptions!AD$2,baseCase_installedCap!$B11:$BC11) -> 234228 | AE13: =AVERAGEIF(baseCase_installedCap!$B$63:$BC$63,assumptions!AE$2,baseCase_installedCap!$B11:$BC11) -> 234228 | AF13: =AVERAGEIF(baseCase_installedCap!$B$63:$BC$63,assumptions!AF$2,baseCase_installedCap!$B11:$BC11) -> 234228 | AG13: =AVERAGEIF(baseCase_installedCap!$B$63:$BC$63,assumptions!AG$2,baseCase_installedCap!$B11:$BC11) -> 234228 | AH13: =AVERAGEIF(baseCase_installedCap!$B$63:$BC$63,assumptions!AH$2,baseCase_installedCap!$B11:$BC11) -> 234228 | AI13: =AVERAGEIF(baseCase_installedCap!$B$63:$BC$63,assumptions!AI$2,baseCase_installedCap!$B11:$BC11) -> 234228 | AJ13: =AVERAGEIF(baseCase_installedCap!$B$63:$BC$63,assumptions!AJ$2,baseCase_installedCap!$B11:$BC11) -> 234228 | AL13: =AVERAGEIF(baseCase_percMembers!$B$63:$BC$63,assumptions!AL$2,baseCase_percMembers!$B11:$BC11) -> 0.589 | AM13: =AVERAGEIF(baseCase_percMembers!$B$63:$BC$63,assumptions!AM$2,baseCase_percMembers!$B11:$BC11) -> 0.589 | AN13: =AVERAGEIF(baseCase_percMembers!$B$63:$BC$63,assumptions!AN$2,baseCase_percMembers!$B11:$BC11) -> 0.589 | AO13: =AVERAGEIF(baseCase_percMembers!$B$63:$BC$63,assumptions!AO$2,baseCase_percMembers!$B11:$BC11) -> 0.589 | AP13: =AVERAGEIF(baseCase_percMembers!$B$63:$BC$63,assumptions!AP$2,baseCase_percMembers!$B11:$BC11) -> 0.589 | AQ13: =AVERAGEIF(baseCase_percMembers!$B$63:$BC$63,assumptions!AQ$2,baseCase_percMembers!$B11:$BC11) -> 0.589 | AR13: =AVERAGEIF(baseCase_percMembers!$B$63:$BC$63,assumptions!AR$2,baseCase_percMembers!$B11:$BC11) -> 0.589 | AS13: =AVERAGEIF(baseCase_percMembers!$B$63:$BC$63,assumptions!AS$2,baseCase_percMembers!$B11:$BC11) -> 0.589 | AT13: =AVERAGEIF(baseCase_percMembers!$B$63:$BC$63,assumptions!AT$2,baseCase_percMembers!$B11:$BC11) -> 0.589
G14: 2019 | H14: =AVERAGEIF(baseCase_projects!$B$63:$BC$63,assumptions!H$2,baseCase_projects!$B12:$BC12) -> 726 | I14: =AVERAGEIF(baseCase_projects!$B$63:$BC$63,assumptions!I$2,baseCase_projects!$B12:$BC12) -> 726 | J14: =AVERAGEIF(baseCase_projects!$B$63:$BC$63,assumptions!J$2,baseCase_projects!$B12:$BC12) -> 726 | K14: =AVERAGEIF(baseCase_projects!$B$63:$BC$63,assumptions!K$2,baseCase_projects!$B12:$BC12) -> 726 | L14: =AVERAGEIF(baseCase_projects!$B$63:$BC$63,assumptions!L$2,baseCase_projects!$B12:$BC12) -> 726 | M14: =AVERAGEIF(baseCase_projects!$B$63:$BC$63,assumptions!M$2,baseCase_projects!$B12:$BC12) -> 726 | N14: =AVERAGEIF(baseCase_projects!$B$63:$BC$63,assumptions!N$2,baseCase_projects!$B12:$BC12) -> 726 | O14: =AVERAGEIF(baseCase_projects!$B$63:$BC$63,assumptions!O$2,baseCase_projects!$B12:$BC12) -> 726 | P14: =AVERAGEIF(baseCase_projects!$B$63:$BC$63,assumptions!P$2,baseCase_projects!$B12:$BC12) -> 726 | R14: =AVERAGEIF(baseCase_ECs!$B$63:$BC$63,assumptions!R$2,baseCase_ECs!$B12:$BC12) -> 560 | S14: =AVERAGEIF(baseCase_ECs!$B$63:$BC$63,assumptions!S$2,baseCase_ECs!$B12:$BC12) -> 560 | T14: =AVERAGEIF(baseCase_ECs!$B$63:$BC$63,assumptions!T$2,baseCase_ECs!$B12:$BC12) -> 560 | U14: =AVERAGEIF(baseCase_ECs!$B$63:$BC$63,assumptions!U$2,baseCase_ECs!$B12:$BC12) -> 560 | V14: =AVERAGEIF(baseCase_ECs!$B$63:$BC$63,assumptions!V$2,baseCase_ECs!$B12:$BC12) -> 560 | W14: =AVERAGEIF(baseCase_ECs!$B$63:$BC$63,assumptions!W$2,baseCase_ECs!$B12:$BC12) -> 560 | X14: =AVERAGEIF(baseCase_ECs!$B$63:$BC$63,assumptions!X$2,baseCase_ECs!$B12:$BC12) -> 560 | Y14: =AVERAGEIF(baseCase_ECs!$B$63:$BC$63,assumptions!Y$2,baseCase_ECs!$B12:$BC12) -> 560 | Z14: =AVERAGEIF(baseCase_ECs!$B$63:$BC$63,assumptions!Z$2,baseCase_ECs!$B12:$BC12) -> 560 | AB14: =AVERAGEIF(baseCase_installedCap!$B$63:$BC$63,assumptions!AB$2,baseCase_installedCap!$B12:$BC12) -> 324522 | AC14: =AVERAGEIF(baseCase_installedCap!$B$63:$BC$63,assumptions!AC$2,baseCase_installedCap!$B12:$BC12) -> 324522 | AD14: =AVERAGEIF(baseCase_installedCap!$B$63:$BC$63,assumptions!AD$2,baseCase_installedCap!$B12:$BC12) -> 324522 | AE14: =AVERAGEIF(baseCase_installedCap!$B$63:$BC$63,assumptions!AE$2,baseCase_installedCap!$B12:$BC12) -> 324522 | AF14: =AVERAGEIF(baseCase_installedCap!$B$63:$BC$63,assumptions!AF$2,baseCase_installedCap!$B12:$BC12) -> 324522 | AG14: =AVERAGEIF(baseCase_installedCap!$B$63:$BC$63,assumptions!AG$2,baseCase_installedCap!$B12:$BC12) -> 324522 | AH14: =AVERAGEIF(baseCase_installedCap!$B$63:$BC$63,assumptions!AH$2,baseCase_installedCap!$B12:$BC12) -> 324522 | AI14: =AVERAGEIF(baseCase_installedCap!$B$63:$BC$63,assumptions!AI$2,baseCase_installedCap!$B12:$BC12) -> 324522 | AJ14: =AVERAGEIF(baseCase_installedCap!$B$63:$BC$63,assumptions!AJ$2,baseCase_installedCap!$B12:$BC12) -> 324522 | AL14: =AVERAGEIF(baseCase_percMembers!$B$63:$BC$63,assumptions!AL$2,baseCase_percMembers!$B12:$BC12) -> 0.816 | AM14: =AVERAGEIF(baseCase_percMembers!$B$63:$BC$63,assumptions!AM$2,baseCase_percMembers!$B12:$BC12) -> 0.816 | AN14: =AVERAGEIF(baseCase_percMembers!$B$63:$BC$63,assumptions!AN$2,baseCase_percMembers!$B12:$BC12) -> 0.816 | AO14: =AVERAGEIF(baseCase_percMembers!$B$63:$BC$63,assumptions!AO$2,baseCase_percMembers!$B12:$BC12) -> 0.816 | AP14: =AVERAGEIF(baseCase_percMembers!$B$63:$BC$63,assumptions!AP$2,baseCase_percMembers!$B12:$BC12) -> 0.816 | AQ14: =AVERAGEIF(baseCase_percMembers!$B$63:$BC$63,assumptions!AQ$2,baseCase_percMembers!$B12:$BC12) -> 0.816 | AR14: =AVERAGEIF(baseCase_percMembers!$B$63:$BC$63,assumptions!AR$2,baseCase_percMembers!$B12:$BC12) -> 0.816 | AS14: =AVERAGEIF(baseCase_percMembers!$B$63:$BC$63,assumptions!AS$2,baseCase_percMembers!$B12:$BC12) -> 0.816 | AT14: =AVERAGEIF(baseCase_percMembers!$B$63:$BC$63,assumptions!AT$2,baseCase_percMembers!$B12:$BC12) -> 0.816
G15: 2020 | H15: =AVERAGEIF(baseCase_projects!$B$63:$BC$63,assumptions!H$2,baseCase_projects!$B13:$BC13) -> 898 | I15: =AVERAGEIF(baseCase_projects!$B$63:$BC$63,assumptions!I$2,baseCase_projects!$B13:$BC13) -> 898 | J15: =AVERAGEIF(baseCase_projects!$B$63:$BC$63,assumptions!J$2,baseCase_projects!$B13:$BC13) -> 898 | K15: =AVERAGEIF(baseCase_projects!$B$63:$BC$63,assumptions!K$2,baseCase_projects!$B13:$BC13) -> 898 | L15: =AVERAGEIF(baseCase_projects!$B$63:$BC$63,assumptions!L$2,baseCase_projects!$B13:$BC13) -> 898 | M15: =AVERAGEIF(baseCase_projects!$B$63:$BC$63,assumptions!M$2,baseCase_projects!$B13:$BC13) -> 898 | N15: =AVERAGEIF(baseCase_projects!$B$63:$BC$63,assumptions!N$2,baseCase_projects!$B13:$BC13) -> 898 | O15: =AVERAGEIF(baseCase_projects!$B$63:$BC$63,assumptions!O$2,baseCase_projects!$B13:$BC13) -> 898 | P15: =AVERAGEIF(baseCase_projects!$B$63:$BC$63,assumptions!P$2,baseCase_projects!$B13:$BC13) -> 898 | R15: =AVERAGEIF(baseCase_ECs!$B$63:$BC$63,assumptions!R$2,baseCase_ECs!$B13:$BC13) -> 613 | S15: =AVERAGEIF(baseCase_ECs!$B$63:$BC$63,assumptions!S$2,baseCase_ECs!$B13:$BC13) -> 613 | T15: =AVERAGEIF(baseCase_ECs!$B$63:$BC$63,assumptions!T$2,baseCase_ECs!$B13:$BC13) -> 613 | U15: =AVERAGEIF(baseCase_ECs!$B$63:$BC$63,assumptions!U$2,baseCase_ECs!$B13:$BC13) -> 613 | V15: =AVERAGEIF(baseCase_ECs!$B$63:$BC$63,assumptions!V$2,baseCase_ECs!$B13:$BC13) -> 613 | W15: =AVERAGEIF(baseCase_ECs!$B$63:$BC$63,assumptions!W$2,baseCase_ECs!$B13:$BC13) -> 613 | X15: =AVERAGEIF(baseCase_ECs!$B$63:$BC$63,assumptions!X$2,baseCase_ECs!$B13:$BC13) -> 613 | Y15: =AVERAGEIF(baseCase_ECs!$B$63:$BC$63,assumptions!Y$2,baseCase_ECs!$B13:$BC13) -> 613 | Z15: =AVERAGEIF(baseCase_ECs!$B$63:$BC$63,assumptions!Z$2,baseCase_ECs!$B13:$BC13) -> 613 | AB15: =AVERAGEIF(baseCase_installedCap!$B$63:$BC$63,assumptions!AB$2,baseCase_installedCap!$B13:$BC13) -> 401406 | AC15: =AVERAGEIF(baseCase_installedCap!$B$63:$BC$63,assumptions!AC$2,baseCase_installedCap!$B13:$BC13) -> 401406 | AD15: =AVERAGEIF(baseCase_installedCap!$B$63:$BC$63,assumptions!AD$2,baseCase_installedCap!$B13:$BC13) -> 401406 | AE15: =AVERAGEIF(baseCase_installedCap!$B$63:$BC$63,assumptions!AE$2,baseCase_installedCap!$B13:$BC13) -> 401406 | AF15: =AVERAGEIF(baseCase_installedCap!$B$63:$BC$63,assumptions!AF$2,baseCase_installedCap!$B13:$BC13) -> 401406 | AG15: =AVERAGEIF(baseCase_installedCap!$B$63:$BC$63,assumptions!AG$2,baseCase_installedCap!$B13:$BC13) -> 401406 | AH15: =AVERAGEIF(baseCase_installedCap!$B$63:$BC$63,assumptions!AH$2,baseCase_installedCap!$B13:$BC13) -> 401406 | AI15: =AVERAGEIF(baseCase_installedCap!$B$63:$BC$63,assumptions!AI$2,baseCase_installedCap!$B13:$BC13) -> 401406 | AJ15: =AVERAGEIF(baseCase_installedCap!$B$63:$BC$63,assumptions!AJ$2,baseCase_installedCap!$B13:$BC13) -> 401406 | AL15: =AVERAGEIF(baseCase_percMembers!$B$63:$BC$63,assumptions!AL$2,baseCase_percMembers!$B13:$BC13) -> 1.01 | AM15: =AVERAGEIF(baseCase_percMembers!$B$63:$BC$63,assumptions!AM$2,baseCase_percMembers!$B13:$BC13) -> 1.01 | AN15: =AVERAGEIF(baseCase_percMembers!$B$63:$BC$63,assumptions!AN$2,baseCase_percMembers!$B13:$BC13) -> 1.01 | AO15: =AVERAGEIF(baseCase_percMembers!$B$63:$BC$63,assumptions!AO$2,baseCase_percMembers!$B13:$BC13) -> 1.01 | AP15: =AVERAGEIF(baseCase_percMembers!$B$63:$BC$63,assumptions!AP$2,baseCase_percMembers!$B13:$BC13) -> 1.01 | AQ15: =AVERAGEIF(baseCase_percMembers!$B$63:$BC$63,assumptions!AQ$2,baseCase_percMembers!$B13:$BC13) -> 1.01 | AR15: =AVERAGEIF(baseCase_percMembers!$B$63:$BC$63,assumptions!AR$2,baseCase_percMembers!$B13:$BC13) -> 1.01 | AS15: =AVERAGEIF(baseCase_percMembers!$B$63:$BC$63,assumptions!AS$2,baseCase_percMembers!$B13:$BC13) -> 1.01 | AT15: =AVERAGEIF(baseCase_percMembers!$B$63:$BC$63,assumptions!AT$2,baseCase_percMembers!$B13:$BC13) -> 1.01
G16: 2021 | H16: =AVERAGEIF(baseCase_projects!$B$63:$BC$63,assumptions!H$2,baseCase_projects!$B14:$BC14) -> 1025 | I16: =AVERAGEIF(baseCase_projects!$B$63:$BC$63,assumptions!I$2,baseCase_projects!$B14:$BC14) -> 1025 | J16: =AVERAGEIF(baseCase_projects!$B$63:$BC$63,assumptions!J$2,baseCase_projects!$B14:$BC14) -> 1025 | K16: =AVERAGEIF(baseCase_projects!$B$63:$BC$63,assumptions!K$2,baseCase_projects!$B14:$BC14) -> 1025 | L16: =AVERAGEIF(baseCase_projects!$B$63:$BC$63,assumptions!L$2,baseCase_projects!$B14:$BC14) -> 1025 | M16: =AVERAGEIF(baseCase_projects!$B$63:$BC$63,assumptions!M$2,baseCase_projects!$B14:$BC14) -> 1025 | N16: =AVERAGEIF(baseCase_projects!$B$63:$BC$63,assumptions!N$2,baseCase_projects!$B14:$BC14) -> 1025 | O16: =AVERAGEIF(baseCase_projects!$B$63:$BC$63,assumptions!O$2,baseCase_projects!$B14:$BC14) -> 1025 | P16: =AVERAGEIF(baseCase_projects!$B$63:$BC$63,assumptions!P$2,baseCase_projects!$B14:$BC14) -> 1025 | R16: =AVERAGEIF(baseCase_ECs!$B$63:$BC$63,assumptions!R$2,baseCase_ECs!$B14:$BC14) -> 663 | S16: =AVERAGEIF(baseCase_ECs!$B$63:$BC$63,assumptions!S$2,baseCase_ECs!$B14:$BC14) -> 663 | T16: =AVERAGEIF(baseCase_ECs!$B$63:$BC$63,assumptions!T$2,baseCase_ECs!$B14:$BC14) -> 663 | U16: =AVERAGEIF(baseCase_ECs!$B$63:$BC$63,assumptions!U$2,baseCase_ECs!$B14:$BC14) -> 663 | V16: =AVERAGEIF(baseCase_ECs!$B$63:$BC$63,assumptions!V$2,baseCase_ECs!$B14:$BC14) -> 663 | W16: =AVERAGEIF(baseCase_ECs!$B$63:$BC$63,assumptions!W$2,baseCase_ECs!$B14:$BC14) -> 663 | X16: =AVERAGEIF(baseCase_ECs!$B$63:$BC$63,assumptions!X$2,baseCase_ECs!$B14:$BC14) -> 663 | Y16: =AVERAGEIF(baseCase_ECs!$B$63:$BC$63,assumptions!Y$2,baseCase_ECs!$B14:$BC14) -> 663 | Z16: =AVERAGEIF(baseCase_ECs!$B$63:$BC$63,assumptions!Z$2,baseCase_ECs!$B14:$BC14) -> 663 | AB16: =AVERAGEIF(baseCase_installedCap!$B$63:$BC$63,assumptions!AB$2,baseCase_installedCap!$B14:$BC14) -> 458175 | AC16: =AVERAGEIF(baseCase_installedCap!$B$63:$BC$63,assumptions!AC$2,baseCase_installedCap!$B14:$BC14) -> 458175 | AD16: =AVERAGEIF(baseCase_installedCap!$B$63:$BC$63,assumptions!AD$2,baseCase_installedCap!$B14:$BC14) -> 458175 | AE16: =AVERAGEIF(baseCase_installedCap!$B$63:$BC$63,assumptions!AE$2,baseCase_installedCap!$B14:$BC14) -> 458175 | AF16: =AVERAGEIF(baseCase_installedCap!$B$63:$BC$63,assumptions!AF$2,baseCase_installedCap!$B14:$BC14) -> 458175 | AG16: =AVERAGEIF(baseCase_installedCap!$B$63:$BC$63,assumptions!AG$2,baseCase_installedCap!$B14:$BC14) -> 458175 | AH16: =AVERAGEIF(baseCase_installedCap!$B$63:$BC$63,assumptions!AH$2,baseCase_installedCap!$B14:$BC14) -> 458175 | AI16: =AVERAGEIF(baseCase_installedCap!$B$63:$BC$63,assumptions!AI$2,baseCase_installedCap!$B14:$BC14) -> 458175 | AJ16: =AVERAGEIF(baseCase_installedCap!$B$63:$BC$63,assumptions!AJ$2,baseCase_installedCap!$B14:$BC14) -> 458175 | AL16: =AVERAGEIF(baseCase_percMembers!$B$63:$BC$63,assumptions!AL$2,baseCase_percMembers!$B14:$BC14) -> 1.153 | AM16: =AVERAGEIF(baseCase_percMembers!$B$63:$BC$63,assumptions!AM$2,baseCase_percMembers!$B14:$BC14) -> 1.153 | AN16: =AVERAGEIF(baseCase_percMembers!$B$63:$BC$63,assumptions!AN$2,baseCase_percMembers!$B14:$BC14) -> 1.153 | AO16: =AVERAGEIF(baseCase_percMembers!$B$63:$BC$63,assumptions!AO$2,baseCase_percMembers!$B14:$BC14) -> 1.153 | AP16: =AVERAGEIF(baseCase_percMembers!$B$63:$BC$63,assumptions!AP$2,baseCase_percMembers!$B14:$BC14) -> 1.153 | AQ16: =AVERAGEIF(baseCase_percMembers!$B$63:$BC$63,assumptions!AQ$2,baseCase_percMembers!$B14:$BC14) -> 1.153 | AR16: =AVERAGEIF(baseCase_percMembers!$B$63:$BC$63,assumptions!AR$2,baseCase_percMembers!$B14:$BC14) -> 1.153 | AS16: =AVERAGEIF(baseCase_percMembers!$B$63:$BC$63,assumptions!AS$2,baseCase_percMembers!$B14:$BC14) -> 1.153 | AT16: =AVERAGEIF(baseCase_percMembers!$B$63:$BC$63,assumptions!AT$2,baseCase_percMembers!$B14:$BC14) -> 1.153
G17: 2022 | H17: =AVERAGEIF(baseCase_projects!$B$63:$BC$63,assumptions!H$2,baseCase_projects!$B15:$BC15) -> 1210 | I17: =AVERAGEIF(baseCase_projects!$B$63:$BC$63,assumptions!I$2,baseCase_projects!$B15:$BC15) -> 1210 | J17: =AVERAGEIF(baseCase_projects!$B$63:$BC$63,assumptions!J$2,baseCase_projects!$B15:$BC15) -> 1210 | K17: =AVERAGEIF(baseCase_projects!$B$63:$BC$63,assumptions!K$2,baseCase_projects!$B15:$BC15) -> 1210 | L17: =AVERAGEIF(baseCase_projects!$B$63:$BC$63,assumptions!L$2,baseCase_projects!$B15:$BC15) -> 1210 | M17: =AVERAGEIF(baseCase_projects!$B$63:$BC$63,assumptions!M$2,baseCase_projects!$B15:$BC15) -> 1210 | N17: =AVERAGEIF(baseCase_projects!$B$63:$BC$63,assumptions!N$2,baseCase_projects!$B15:$BC15) -> 1210 | O17: =AVERAGEIF(baseCase_projects!$B$63:$BC$63,assumptions!O$2,baseCase_projects!$B15:$BC15) -> 1210 | P17: =AVERAGEIF(baseCase_projects!$B$63:$BC$63,assumptions!P$2,baseCase_projects!$B15:$BC15) -> 1210 | R17: =AVERAGEIF(baseCase_ECs!$B$63:$BC$63,assumptions!R$2,baseCase_ECs!$B15:$BC15) -> 688 | S17: =AVERAGEIF(baseCase_ECs!$B$63:$BC$63,assumptions!S$2,baseCase_ECs!$B15:$BC15) -> 688 | T17: =AVERAGEIF(baseCase_ECs!$B$63:$BC$63,assumptions!T$2,baseCase_ECs!$B15:$BC15) -> 688 | U17: =AVERAGEIF(baseCase_ECs!$B$63:$BC$63,assumptions!U$2,baseCase_ECs!$B15:$BC15) -> 688 | V17: =AVERAGEIF(baseCase_ECs!$B$63:$BC$63,assumptions!V$2,baseCase_ECs!$B15:$BC15) -> 688 | W17: =AVERAGEIF(baseCase_ECs!$B$63:$BC$63,assumptions!W$2,baseCase_ECs!$B15:$BC15) -> 688 | X17: =AVERAGEIF(baseCase_ECs!$B$63:$BC$63,assumptions!X$2,baseCase_ECs!$B15:$BC15) -> 688 | Y17: =AVERAGEIF(baseCase_ECs!$B$63:$BC$63,assumptions!Y$2,baseCase_ECs!$B15:$BC15) -> 688 | Z17: =AVERAGEIF(baseCase_ECs!$B$63:$BC$63,assumptions!Z$2,baseCase_ECs!$B15:$BC15) -> 688 | AB17: =AVERAGEIF(baseCase_installedCap!$B$63:$BC$63,assumptions!AB$2,baseCase_installedCap!$B15:$BC15) -> 540870 | AC17: =AVERAGEIF(baseCase_installedCap!$B$63:$BC$63,assumptions!AC$2,baseCase_installedCap!$B15:$BC15) -> 540870 | AD17: =AVERAGEIF(baseCase_installedCap!$B$63:$BC$63,assumptions!AD$2,baseCase_installedCap!$B15:$BC15) -> 540870 | AE17: =AVERAGEIF(baseCase_installedCap!$B$63:$BC$63,assumptions!AE$2,baseCase_installedCap!$B15:$BC15) -> 540870 | AF17: =AVERAGEIF(baseCase_installedCap!$B$63:$BC$63,assumptions!AF$2,baseCase_installedCap!$B15:$BC15) -> 540870 | AG17: =AVERAGEIF(baseCase_installedCap!$B$63:$BC$63,assumptions!AG$2,baseCase_installedCap!$B15:$BC15) -> 540870 | AH17: =AVERAGEIF(baseCase_installedCap!$B$63:$BC$63,assumptions!AH$2,baseCase_installedCap!$B15:$BC15) -> 540870 | AI17: =AVERAGEIF(baseCase_installedCap!$B$63:$BC$63,assumptions!AI$2,baseCase_installedCap!$B15:$BC15) -> 540870 | AJ17: =AVERAGEIF(baseCase_installedCap!$B$63:$BC$63,assumptions!AJ$2,baseCase_installedCap!$B15:$BC15) -> 540870 | AL17: =AVERAGEIF(baseCase_percMembers!$B$63:$BC$63,assumptions!AL$2,baseCase_percMembers!$B15:$BC15) -> 1.361 | AM17: =AVERAGEIF(baseCase_percMembers!$B$63:$BC$63,assumptions!AM$2,baseCase_percMembers!$B15:$BC15) -> 1.361 | AN17: =AVERAGEIF(baseCase_percMembers!$B$63:$BC$63,assumptions!AN$2,baseCase_percMembers!$B15:$BC15) -> 1.361 | AO17: =AVERAGEIF(baseCase_percMembers!$B$63:$BC$63,assumptions!AO$2,baseCase_percMembers!$B15:$BC15) -> 1.361 | AP17: =AVERAGEIF(baseCase_percMembers!$B$63:$BC$63,assumptions!AP$2,baseCase_percMembers!$B15:$BC15) -> 1.361 | AQ17: =AVERAGEIF(baseCase_percMembers!$B$63:$BC$63,assumptions!AQ$2,baseCase_percMembers!$B15:$BC15) -> 1.361 | AR17: =AVERAGEIF(baseCase_percMembers!$B$63:$BC$63,assumptions!AR$2,baseCase_percMembers!$B15:$BC15) -> 1.361 | AS17: =AVERAGEIF(baseCase_percMembers!$B$63:$BC$63,assumptions!AS$2,baseCase_percMembers!$B15:$BC15) -> 1.361 | AT17: =AVERAGEIF(baseCase_percMembers!$B$63:$BC$63,assumptions!AT$2,baseCase_percMembers!$B15:$BC15) -> 1.361
G18: 2023 | H18: =AVERAGEIF(baseCase_projects!$B$63:$BC$63,assumptions!H$2,baseCase_projects!$B16:$BC16) -> 1374 | I18: =AVERAGEIF(baseCase_projects!$B$63:$BC$63,assumptions!I$2,baseCase_projects!$B16:$BC16) -> 1374 | J18: =AVERAGEIF(baseCase_projects!$B$63:$BC$63,assumptions!J$2,baseCase_projects!$B16:$BC16) -> 1374 | K18: =AVERAGEIF(baseCase_projects!$B$63:$BC$63,assumptions!K$2,baseCase_projects!$B16:$BC16) -> 1374 | L18: =AVERAGEIF(baseCase_projects!$B$63:$BC$63,assumptions!L$2,baseCase_projects!$B16:$BC16) -> 1374 | M18: =AVERAGEIF(baseCase_projects!$B$63:$BC$63,assumptions!M$2,baseCase_projects!$B16:$BC16) -> 1374 | N18: =AVERAGEIF(baseCase_projects!$B$63:$BC$63,assumptions!N$2,baseCase_projects!$B16:$BC16) -> 1374 | O18: =AVERAGEIF(baseCase_projects!$B$63:$BC$63,assumptions!O$2,baseCase_projects!$B16:$BC16) -> 1374 | P18: =AVERAGEIF(baseCase_projects!$B$63:$BC$63,assumptions!P$2,baseCase_projects!$B16:$BC16) -> 1374 | R18: =AVERAGEIF(baseCase_ECs!$B$63:$BC$63,assumptions!R$2,baseCase_ECs!$B16:$BC16) -> 692 | S18: =AVERAGEIF(baseCase_ECs!$B$63:$BC$63,assumptions!S$2,baseCase_ECs!$B16:$BC16) -> 692 | T18: =AVERAGEIF(baseCase_ECs!$B$63:$BC$63,assumptions!T$2,baseCase_ECs!$B16:$BC16) -> 692 | U18: =AVERAGEIF(baseCase_ECs!$B$63:$BC$63,assumptions!U$2,baseCase_ECs!$B16:$BC16) -> 692 | V18: =AVERAGEIF(baseCase_ECs!$B$63:$BC$63,assumptions!V$2,baseCase_ECs!$B16:$BC16) -> 692 | W18: =AVERAGEIF(baseCase_ECs!$B$63:$BC$63,assumptions!W$2,baseCase_ECs!$B16:$BC16) -> 692 | X18: =AVERAGEIF(baseCase_ECs!$B$63:$BC$63,assumptions!X$2,baseCase_ECs!$B16:$BC16) -> 692 | Y18: =AVERAGEIF(baseCase_ECs!$B$63:$BC$63,assumptions!Y$2,baseCase_ECs!$B16:$BC16) -> 692 | Z18: =AVERAGEIF(baseCase_ECs!$B$63:$BC$63,assumptions!Z$2,baseCase_ECs!$B16:$BC16) -> 692 | AB18: =AVERAGEIF(baseCase_installedCap!$B$63:$BC$63,assumptions!AB$2,baseCase_installedCap!$B16:$BC16) -> 614178 | AC18: =AVERAGEIF(baseCase_installedCap!$B$63:$BC$63,assumptions!AC$2,baseCase_installedCap!$B16:$BC16) -> 614178 | AD18: =AVERAGEIF(baseCase_installedCap!$B$63:$BC$63,assumptions!AD$2,baseCase_installedCap!$B16:$BC16) -> 614178 | AE18: =AVERAGEIF(baseCase_installedCap!$B$63:$BC$63,assumptions!AE$2,baseCase_installedCap!$B16:$BC16) -> 614178 | AF18: =AVERAGEIF(baseCase_installedCap!$B$63:$BC$63,assumptions!AF$2,baseCase_installedCap!$B16:$BC16) -> 614178 | AG18: =AVERAGEIF(baseCase_installedCap!$B$63:$BC$63,assumptions!AG$2,baseCase_installedCap!$B16:$BC16) -> 614178 | AH18: =AVERAGEIF(baseCase_installedCap!$B$63:$BC$63,assumptions!AH$2,baseCase_installedCap!$B16:$BC16) -> 614178 | AI18: =AVERAGEIF(baseCase_installedCap!$B$63:$BC$63,assumptions!AI$2,baseCase_installedCap!$B16:$BC16) -> 614178 | AJ18: =AVERAGEIF(baseCase_installedCap!$B$63:$BC$63,assumptions!AJ$2,baseCase_installedCap!$B16:$BC16) -> 614178 | AL18: =AVERAGEIF(baseCase_percMembers!$B$63:$BC$63,assumptions!AL$2,baseCase_percMembers!$B16:$BC16) -> 1.545 | AM18: =AVERAGEIF(baseCase_percMembers!$B$63:$BC$63,assumptions!AM$2,baseCase_percMembers!$B16:$BC16) -> 1.545 | AN18: =AVERAGEIF(baseCase_percMembers!$B$63:$BC$63,assumptions!AN$2,baseCase_percMembers!$B16:$BC16) -> 1.545 | AO18: =AVERAGEIF(baseCase_percMembers!$B$63:$BC$63,assumptions!AO$2,baseCase_percMembers!$B16:$BC16) -> 1.545 | AP18: =AVERAGEIF(baseCase_percMembers!$B$63:$BC$63,assumptions!AP$2,baseCase_percMembers!$B16:$BC16) -> 1.545 | AQ18: =AVERAGEIF(baseCase_percMembers!$B$63:$BC$63,assumptions!AQ$2,baseCase_percMembers!$B16:$BC16) -> 1.545 | AR18: =AVERAGEIF(baseCase_percMembers!$B$63:$BC$63,assumptions!AR$2,baseCase_percMembers!$B16:$BC16) -> 1.545 | AS18: =AVERAGEIF(baseCase_percMembers!$B$63:$BC$63,assumptions!AS$2,baseCase_percMembers!$B16:$BC16) -> 1.545 | AT18: =AVERAGEIF(baseCase_percMembers!$B$63:$BC$63,assumptions!AT$2,baseCase_percMembers!$B16:$BC16) -> 1.545
